<?xml version="1.0" ?>
<!-- =================================================================================== -->
<!-- |    This document was autogenerated by xacro from /opt/ros/kinetic/share/moveit_resources/panda_description/urdf/panda.urdf | -->
<!-- |    EDITING THIS FILE BY HAND IS NOT RECOMMENDED                                 | -->
<!-- =================================================================================== -->
<robot name="panda" xmlns:xacro="http://www.ros.org/wiki/xacro">
    <link name="base_link">
      </link>
    <joint name="base_joint" type="fixed">
        <origin rpy="0 0 0" xyz="0 0 0.0" />
        <parent link="base_link" />
        <child link="panda_link0" />
    </joint>
    <link name="panda_link0">
        <visual>
            <geometry>
                <mesh filename="meshes_cup/visual/link0.dae" />
            </geometry>
        </visual>
        <collision>
            <geometry>
                <mesh filename="meshes_cup/collision/link0.stl" />
            </geometry>
        </collision>
    </link>
    <link name="panda_link1">
        <visual>
            <geometry>
                <mesh filename="meshes_cup/visual/link1.dae" />
            </geometry>
        </visual>
        <collision>
            <geometry>
                <mesh filename="meshes_cup/collision/link1.stl" />
            </geometry>
        </collision>
    </link>
    <joint name="panda_joint1" type="revolute">
        <safety_controller k_position="100.0" k_velocity="40.0" soft_lower_limit="-2.8073" soft_upper_limit="2.8073" />
        <origin rpy="0 0 0" xyz="0 0 0.333" />
        <parent link="panda_link0" />
        <child link="panda_link1" />
        <axis xyz="0 0 1" />
        <limit effort="87" lower="-2.8073" upper="2.8073" velocity="2.3925" />
    </joint>
    <link name="panda_link2">
        <visual>
            <geometry>
                <mesh filename="meshes_cup/visual/link2.dae" />
            </geometry>
        </visual>
        <collision>
            <geometry>
                <mesh filename="meshes_cup/collision/link2.stl" />
            </geometry>
        </collision>
    </link>
    <joint name="panda_joint2" type="revolute">
        <safety_controller k_position="100.0" k_velocity="40.0" soft_lower_limit="-1.7028" soft_upper_limit="1.7028" />
        <origin rpy="-1.57079632679 0 0" xyz="0 0 0" />
        <parent link="panda_link1" />
        <child link="panda_link2" />
        <axis xyz="0 0 1" />
        <limit effort="87" lower="-1.7028" upper="1.7028" velocity="2.3925" />
    </joint>
    <link name="panda_link3">
        <visual>
            <geometry>
                <mesh filename="meshes_cup/visual/link3.dae" />
            </geometry>
        </visual>
        <collision>
            <geometry>
                <mesh filename="meshes_cup/collision/link3.stl" />
            </geometry>
        </collision>
    </link>
    <joint name="panda_joint3" type="revolute">
        <safety_controller k_position="100.0" k_velocity="40.0" soft_lower_limit="-2.8073" soft_upper_limit="2.8073" />
        <origin rpy="1.57079632679 0 0" xyz="0 -0.316 0" />
        <parent link="panda_link2" />
        <child link="panda_link3" />
        <axis xyz="0 0 1" />
        <limit effort="87" lower="-2.8073" upper="2.8073" velocity="2.3925" />
    </joint>
    <link name="panda_link4">
        <visual>
            <geometry>
                <mesh filename="meshes_cup/visual/link4.dae" />
            </geometry>
        </visual>
        <collision>
            <geometry>
                <mesh filename="meshes_cup/collision/link4.stl" />
            </geometry>
        </collision>
    </link>
    <joint name="panda_joint4" type="revolute">
        <safety_controller k_position="100.0" k_velocity="40.0" soft_lower_limit="-3.0018" soft_upper_limit="-0.1298" />
        <origin rpy="1.57079632679 0 0" xyz="0.0825 0 0" />
        <parent link="panda_link3" />
        <child link="panda_link4" />
        <axis xyz="0 0 1" />
        <limit effort="87" lower="-3.0018" upper="-0.1298" velocity="2.3925" />
    </joint>
    <link name="panda_link5">
        <visual>
            <geometry>
                <mesh filename="meshes_cup/visual/link5.dae" />
            </geometry>
        </visual>
        <collision>
            <geometry>
                <mesh filename="meshes_cup/collision/link5.stl" />
            </geometry>
        </collision>
    </link>
    <joint name="panda_joint5" type="revolute">
        <safety_controller k_position="100.0" k_velocity="40.0" soft_lower_limit="-2.8073" soft_upper_limit="2.8073" />
        <origin rpy="-1.57079632679 0 0" xyz="-0.0825 0.384 0" />
        <parent link="panda_link4" />
        <child link="panda_link5" />
        <axis xyz="0 0 1" />
        <limit effort="12" lower="-2.8073" upper="2.8073" velocity="2.8710" />
    </joint>
    <link name="panda_link6">
        <visual>
            <geometry>
                <mesh filename="meshes_cup/visual/link6.dae" />
            </geometry>
        </visual>
        <collision>
            <geometry>
                <mesh filename="meshes_cup/collision/link6.stl" />
            </geometry>
        </collision>
    </link>
    <joint name="panda_joint6" type="revolute">
        <safety_controller k_position="100.0" k_velocity="40.0" soft_lower_limit="0.0775" soft_upper_limit="3.7025" />
        <origin rpy="1.57079632679 0 0" xyz="0 0 0" />
        <parent link="panda_link5" />
        <child link="panda_link6" />
        <axis xyz="0 0 1" />
        <limit effort="12" lower="0.0775" upper="3.7025" velocity="2.8710" />
    </joint>
    <link name="panda_link7">
        <visual>
            <geometry>
                <mesh filename="meshes_cup/visual/link7.dae" />
            </geometry>
        </visual>
        <collision>
            <geometry>
                <mesh filename="meshes_cup/collision/link7.stl" />
            </geometry>
        </collision>
    </link>
    <joint name="panda_joint7" type="revolute">
        <safety_controller k_position="100.0" k_velocity="40.0" soft_lower_limit="-2.8073" soft_upper_limit="2.8073" />
        <origin rpy="1.57079632679 0 0" xyz="0.088 0 0" />
        <parent link="panda_link6" />
        <child link="panda_link7" />
        <axis xyz="0 0 1" />
        <limit effort="12" lower="-2.8073" upper="2.8073" velocity="2.8710" />
    </joint>
    <!-- <link name="panda_link8" />
    <joint name="panda_joint8" type="fixed">
        <origin rpy="0 0 0" xyz="0 0 0.107" />
        <parent link="panda_link7" />
        <child link="panda_link8" />
        <axis xyz="0 0 0" />
    </joint> -->

    <!-- <link name="camera_link"/>
    <joint name="camera_joint" type="fixed">
        <origin rpy="0.0183591 0.0096417 -2.3317167" xyz="0.07247900537625587 -0.015971556564201184 0.035149015963409073"/>
        <parent link="panda_link8"/>
        <child link="camera_link"/>
        <axis xyz="0 0 1"/>
    </joint> -->

    <joint name="gripper_joint" type="fixed">
        <parent link="panda_link7" />
        <child link="gripper" />
        <origin rpy="0 0 -0.785398163397" xyz="0 0 0.107"/>
    </joint>
    <link name="gripper">
        <visual>
            <origin rpy="-1.57 0.0 0.0" xyz="0 0 0.0"/>
            <geometry>
                <mesh filename="meshes_cup/visual/piab_single_cup.dae" />
            </geometry>
        </visual>
        <collision>
            <geometry>
                <mesh filename="meshes_cup/collision/piab_single_cup.stl" />
            </geometry>
        </collision>
    </link>
  
    <joint name="cup_joint" type="fixed">
        <origin rpy="0 0 0" xyz="0 0 0"/>
        <parent link="gripper"/>
        <child link="cup"/>
        <axis xyz="0 0 1"/>
    </joint>
    <link name="cup">
        <visual>
          <origin xyz="0 0 0.195" rpy="0 0 0" />
             <geometry>
               <cylinder radius="0.012" length="0.16"/>
             </geometry>
             <material name="Cyan">
                 <color rgba="0 1.0 1.0 1.0"/>
             </material>
         </visual>
         <collision>
             <origin xyz="0 0 0.195" rpy="0 0 0"/>
             <geometry>
               <cylinder radius="0.012" length="0.16"/>
             </geometry>
         </collision>
    </link>

     <!-- tcp -->
    <joint name="tcp_joint" type="fixed">
        <origin rpy="0 0 0" xyz="0 0 0.275"/>
        <parent link="cup"/>
        <child link="tcp"/>
    </joint>
    <link name="tcp"/>

</robot>
